[2023-08-23T16:25:43.808+0000] {taskinstance.py:1165} INFO - Dependencies all met for <TaskInstance: tbf_analysis_dag_v15.create_dataproc_cluster_task manual__2023-08-23T16:25:36.638615+00:00 [queued]>
[2023-08-23T16:25:43.814+0000] {taskinstance.py:1165} INFO - Dependencies all met for <TaskInstance: tbf_analysis_dag_v15.create_dataproc_cluster_task manual__2023-08-23T16:25:36.638615+00:00 [queued]>
[2023-08-23T16:25:43.814+0000] {taskinstance.py:1362} INFO - 
--------------------------------------------------------------------------------
[2023-08-23T16:25:43.815+0000] {taskinstance.py:1363} INFO - Starting attempt 1 of 2
[2023-08-23T16:25:43.815+0000] {taskinstance.py:1364} INFO - 
--------------------------------------------------------------------------------
[2023-08-23T16:25:43.823+0000] {taskinstance.py:1383} INFO - Executing <Task(DataprocCreateClusterOperator): create_dataproc_cluster_task> on 2023-08-23 16:25:36.638615+00:00
[2023-08-23T16:25:43.830+0000] {standard_task_runner.py:54} INFO - Started process 123 to run task
[2023-08-23T16:25:43.834+0000] {standard_task_runner.py:82} INFO - Running: ['***', 'tasks', 'run', 'tbf_analysis_dag_v15', 'create_dataproc_cluster_task', 'manual__2023-08-23T16:25:36.638615+00:00', '--job-id', '5', '--raw', '--subdir', 'DAGS_FOLDER/tbf_analysis_dag_v15.py', '--cfg-path', '/tmp/tmp0f3pc45u']
[2023-08-23T16:25:43.837+0000] {standard_task_runner.py:83} INFO - Job 5: Subtask create_dataproc_cluster_task
[2023-08-23T16:25:43.838+0000] {dagbag.py:525} INFO - Filling up the DagBag from /opt/***/dags/tbf_analysis_dag_v15.py
[2023-08-23T16:25:43.946+0000] {task_command.py:384} INFO - Running <TaskInstance: tbf_analysis_dag_v15.create_dataproc_cluster_task manual__2023-08-23T16:25:36.638615+00:00 [running]> on host 6cd4c2af8145
[2023-08-23T16:25:43.992+0000] {taskinstance.py:1592} INFO - Exporting the following env vars:
AIRFLOW_CTX_DAG_OWNER=***
AIRFLOW_CTX_DAG_ID=tbf_analysis_dag_v15
AIRFLOW_CTX_TASK_ID=create_dataproc_cluster_task
AIRFLOW_CTX_EXECUTION_DATE=2023-08-23T16:25:36.638615+00:00
AIRFLOW_CTX_TRY_NUMBER=1
AIRFLOW_CTX_DAG_RUN_ID=manual__2023-08-23T16:25:36.638615+00:00
[2023-08-23T16:25:43.993+0000] {dataproc.py:590} INFO - Creating cluster: trans-border-freights-394419_dataproc
[2023-08-23T16:25:43.994+0000] {crypto.py:84} WARNING - empty cryptography key - values will not be stored encrypted.
[2023-08-23T16:25:43.994+0000] {base.py:71} INFO - Using connection ID 'google_cloud_default' for task execution.
[2023-08-23T16:25:44.414+0000] {taskinstance.py:1851} ERROR - Task failed with exception
Traceback (most recent call last):
  File "/home/airflow/.local/lib/python3.7/site-packages/google/api_core/grpc_helpers.py", line 50, in error_remapped_callable
    return callable_(*args, **kwargs)
  File "/home/airflow/.local/lib/python3.7/site-packages/grpc/_channel.py", line 946, in __call__
    return _end_unary_response_blocking(state, call, False, None)
  File "/home/airflow/.local/lib/python3.7/site-packages/grpc/_channel.py", line 849, in _end_unary_response_blocking
    raise _InactiveRpcError(state)
grpc._channel._InactiveRpcError: <_InactiveRpcError of RPC that terminated with:
	status = StatusCode.INVALID_ARGUMENT
	details = "Multiple validation errors:
 - Cluster name 'trans-border-freights-394419_dataproc' must match pattern (?:[a-z](?:[-a-z0-9]{0,49}[a-z0-9])?)
 - Storage Bucket name 'gs://tbf-analysis-terraform_trans-border-freights-394419_temp' must match pattern '[a-z0-9\-_.]{3,222}'
 - Zone name is invalid: us-central1"
	debug_error_string = "UNKNOWN:Error received from peer ipv4:142.250.114.95:443 {grpc_message:"Multiple validation errors:\n - Cluster name \'trans-border-freights-394419_dataproc\' must match pattern (?:[a-z](?:[-a-z0-9]{0,49}[a-z0-9])?)\n - Storage Bucket name \'gs://tbf-analysis-terraform_trans-border-freights-394419_temp\' must match pattern \'[a-z0-9\\-_.]{3,222}\'\n - Zone name is invalid: us-central1", grpc_status:3, created_time:"2023-08-23T16:25:44.414157471+00:00"}"
>

The above exception was the direct cause of the following exception:

Traceback (most recent call last):
  File "/home/airflow/.local/lib/python3.7/site-packages/airflow/providers/google/cloud/operators/dataproc.py", line 598, in execute
    cluster = self._create_cluster(hook)
  File "/home/airflow/.local/lib/python3.7/site-packages/airflow/providers/google/cloud/operators/dataproc.py", line 531, in _create_cluster
    metadata=self.metadata,
  File "/home/airflow/.local/lib/python3.7/site-packages/airflow/providers/google/common/hooks/base_google.py", line 463, in inner_wrapper
    return func(self, *args, **kwargs)
  File "/home/airflow/.local/lib/python3.7/site-packages/airflow/providers/google/cloud/hooks/dataproc.py", line 314, in create_cluster
    metadata=metadata,
  File "/home/airflow/.local/lib/python3.7/site-packages/google/cloud/dataproc_v1/services/cluster_controller/client.py", line 564, in create_cluster
    metadata=metadata,
  File "/home/airflow/.local/lib/python3.7/site-packages/google/api_core/gapic_v1/method.py", line 154, in __call__
    return wrapped_func(*args, **kwargs)
  File "/home/airflow/.local/lib/python3.7/site-packages/google/api_core/retry.py", line 288, in retry_wrapped_func
    on_error=on_error,
  File "/home/airflow/.local/lib/python3.7/site-packages/google/api_core/retry.py", line 190, in retry_target
    return target()
  File "/home/airflow/.local/lib/python3.7/site-packages/google/api_core/timeout.py", line 99, in func_with_timeout
    return func(*args, **kwargs)
  File "/home/airflow/.local/lib/python3.7/site-packages/google/api_core/grpc_helpers.py", line 52, in error_remapped_callable
    raise exceptions.from_grpc_error(exc) from exc
google.api_core.exceptions.InvalidArgument: 400 Multiple validation errors:
 - Cluster name 'trans-border-freights-394419_dataproc' must match pattern (?:[a-z](?:[-a-z0-9]{0,49}[a-z0-9])?)
 - Storage Bucket name 'gs://tbf-analysis-terraform_trans-border-freights-394419_temp' must match pattern '[a-z0-9\-_.]{3,222}'
 - Zone name is invalid: us-central1
[2023-08-23T16:25:44.425+0000] {taskinstance.py:1406} INFO - Marking task as UP_FOR_RETRY. dag_id=tbf_analysis_dag_v15, task_id=create_dataproc_cluster_task, execution_date=20230823T162536, start_date=20230823T162543, end_date=20230823T162544
[2023-08-23T16:25:44.433+0000] {standard_task_runner.py:107} ERROR - Failed to execute job 5 for task create_dataproc_cluster_task (400 Multiple validation errors:
 - Cluster name 'trans-border-freights-394419_dataproc' must match pattern (?:[a-z](?:[-a-z0-9]{0,49}[a-z0-9])?)
 - Storage Bucket name 'gs://tbf-analysis-terraform_trans-border-freights-394419_temp' must match pattern '[a-z0-9\-_.]{3,222}'
 - Zone name is invalid: us-central1; 123)
[2023-08-23T16:25:44.447+0000] {local_task_job.py:164} INFO - Task exited with return code 1
[2023-08-23T16:25:44.468+0000] {local_task_job.py:273} INFO - 0 downstream tasks scheduled from follow-on schedule check
