[2023-08-23T13:31:00.368+0000] {taskinstance.py:1165} INFO - Dependencies all met for <TaskInstance: tbf_analysis_dag_v14.create_dataproc_cluster_task scheduled__2023-08-23T00:00:00+00:00 [queued]>
[2023-08-23T13:31:00.374+0000] {taskinstance.py:1165} INFO - Dependencies all met for <TaskInstance: tbf_analysis_dag_v14.create_dataproc_cluster_task scheduled__2023-08-23T00:00:00+00:00 [queued]>
[2023-08-23T13:31:00.375+0000] {taskinstance.py:1362} INFO - 
--------------------------------------------------------------------------------
[2023-08-23T13:31:00.375+0000] {taskinstance.py:1363} INFO - Starting attempt 1 of 2
[2023-08-23T13:31:00.376+0000] {taskinstance.py:1364} INFO - 
--------------------------------------------------------------------------------
[2023-08-23T13:31:00.383+0000] {taskinstance.py:1383} INFO - Executing <Task(DataprocCreateClusterOperator): create_dataproc_cluster_task> on 2023-08-23 00:00:00+00:00
[2023-08-23T13:31:00.388+0000] {standard_task_runner.py:54} INFO - Started process 42636 to run task
[2023-08-23T13:31:00.393+0000] {standard_task_runner.py:82} INFO - Running: ['***', 'tasks', 'run', 'tbf_analysis_dag_v14', 'create_dataproc_cluster_task', 'scheduled__2023-08-23T00:00:00+00:00', '--job-id', '12', '--raw', '--subdir', 'DAGS_FOLDER/tbf_analysis_dag_v14.py', '--cfg-path', '/tmp/tmp9phzkynp']
[2023-08-23T13:31:00.395+0000] {standard_task_runner.py:83} INFO - Job 12: Subtask create_dataproc_cluster_task
[2023-08-23T13:31:00.396+0000] {dagbag.py:525} INFO - Filling up the DagBag from /opt/***/dags/tbf_analysis_dag_v14.py
[2023-08-23T13:31:00.397+0000] {standard_task_runner.py:107} ERROR - Failed to execute job 12 for task create_dataproc_cluster_task (Dag 'tbf_analysis_dag_v14' could not be found; either it does not exist or it failed to parse.; 42636)
[2023-08-23T13:31:00.406+0000] {local_task_job.py:164} INFO - Task exited with return code 1
[2023-08-23T13:31:00.426+0000] {local_task_job.py:273} INFO - 0 downstream tasks scheduled from follow-on schedule check
